Workbook

Sheet Sheet1
A1: VENDOR | B1: CONTRACT_STATUS | C1: START_DATE | D1: END_DATE | E1: TOTAL_CONTRACT_VALUE | F1: TERM_NO | G1: AMOUNT | H1: STATUS | I1: DATE
A2: RAJAWALI KONSULTAN | B2: KONTRAK JASA PAJAK | C2: 45834 | D2: 45469 | E2: 36000000 | F2: 1 | G2: 36000000 | H2: Paid | I2: 45469
A3: PT Mipcon Konsultan Utama | B3: Jasa Soil Test dan Topografi Darat & Laut Sumbawa | C3: 45075 | D3: 45135 | E3: 658096800 | F3: 1 | G3: 131619360 | H3: Paid | I3: 45085
A4: PT Mipcon Konsultan Utama | B4: Jasa Soil Test dan Topografi Darat & Laut Sumbawa | C4: 45075 | D4: 45135 | E4: 658096800 | F4: 2 | G4: 460667760 | H4: Paid | I4: 45131
A5: PT Mipcon Konsultan Utama | B5: Jasa Soil Test dan Topografi Darat & Laut Sumbawa | C5: 45075 | D5: 45135 | E5: 658096800 | F5: 3 | G5: 65809680 | H5: Paid | I5: 45149
A6: PT ATRYA SWASCIPTA REKAYASA | B6: Geolistrik | C6: 45145 | D6: 45176 | E6: 208291500 | F6: 1 | G6: 62487450 | H6: Paid | I6: 45159
A7: PT ATRYA SWASCIPTA REKAYASA | B7: Geolistrik | C7: 45145 | D7: 45176 | E7: 208291500 | F7: 2 | G7: 145804050 | H7: Paid | I7: 45163
A8: PT ATRYA SWASCIPTA REKAYASA | B8: DED | C8: 45145 | D8: 45206 | E8: 2116770000 | F8: 1 | G8: 423354000 | H8: Paid | I8: 45219
A9: PT ATRYA SWASCIPTA REKAYASA | B9: DED | C9: 45145 | D9: 45206 | E9: 2116770000 | F9: 2 | G9: 1058385000 | H9: Paid | I9: 45328
A10: PT ATRYA SWASCIPTA REKAYASA | B10: DED | C10: 45145 | D10: 45206 | E10: 2116770000 | F10: 3 | G10: 635031000 | H10: Paid | I10: 45436
A11: PT ATRYA SWASCIPTA REKAYASA | B11: FEED | C11: 45145 | D11: 45267 | E11: 680985000 | F11: 1 | G11: 136197000 | H11: Paid | I11: 45124
A12: PT ATRYA SWASCIPTA REKAYASA | B12: FEED | C12: 45145 | D12: 45267 | E12: 680985000 | F12: 2 | G12: 340492500 | H12: Paid | I12: 45194
A13: PT ATRYA SWASCIPTA REKAYASA | B13: FEED | C13: 45145 | D13: 45267 | E13: 680985000 | F13: 3 | G13: 204295500 | H13: Paid | I13: 45222
... A48: PT ATRYA TEKNIKA KONSULINDO | B48: PENDAMPING TENDER | C48: 45250 | D48: 45280 | E48: 280497000 | F48: 2 | G48: 254369182 | H48: Paid | I48: 45478
A49: PT ATRYA TEKNIKA KONSULINDO | B49: PENGAWAS PEMBANGUNAN | C49: 45250 | D49: 45817 | E49: =2900000000*1.11 -> 3.219e+09 | F49: 1 | G49: 226258432 | H49: Paid | I49: 45266
A50: PT ATRYA TEKNIKA KONSULINDO | B50: PENGAWAS PEMBANGUNAN | C50: 45250 | D50: 45817 | E50: =2900000000*1.11 -> 3.219e+09 | F50: 2 | G50: 139112864 | H50: Paid | I50: 45538
A51: PT ATRYA TEKNIKA KONSULINDO | B51: PENGAWAS PEMBANGUNAN | C51: 45250 | D51: 45817 | E51: =2900000000*1.11 -> 3.219e+09 | F51: 3 | G51: 159244972 | H51: Paid | I51: 45538
A52: PT ATRYA TEKNIKA KONSULINDO | B52: PENGAWAS PEMBANGUNAN | C52: 45250 | D52: 45817 | E52: =2900000000*1.11 -> 3.219e+09 | F52: 4 | G52: 159244972 | H52: Paid | I52: 45582
A53: PT ATRYA TEKNIKA KONSULINDO | B53: PENGAWAS PEMBANGUNAN | C53: 45250 | D53: 45817 | E53: =2900000000*1.11 -> 3.219e+09 | F53: 5 | G53: 159244972 | H53: Paid | I53: 45618
A54: PT ATRYA TEKNIKA KONSULINDO | B54: PENGAWAS PEMBANGUNAN | C54: 45250 | D54: 45817 | E54: =2900000000*1.11 -> 3.219e+09 | F54: 6 | G54: 159244972 | H54: Paid | I54: 45649
A55: PT ATRYA TEKNIKA KONSULINDO | B55: PENGAWAS PEMBANGUNAN | C55: 45250 | D55: 45817 | E55: =2900000000*1.11 -> 3.219e+09 | F55: 7 | G55: 171324237 | H55: Paid | I55: 45674
A56: PT ATRYA TEKNIKA KONSULINDO | B56: PENGAWAS PEMBANGUNAN | C56: 45250 | D56: 45817 | E56: =2900000000*1.11 -> 3.219e+09 | F56: 8 | G56: 183403501 | H56: Paid | I56: 45708
A57: PT ATRYA TEKNIKA KONSULINDO | B57: PENGAWAS PEMBANGUNAN | C57: 45250 | D57: 45817 | E57: =2900000000*1.11 -> 3.219e+09 | F57: 9 | G57: 183403501 | H57: Paid | I57: 45735
A58: PT ATRYA TEKNIKA KONSULINDO | B58: PENGAWAS PEMBANGUNAN | C58: 45250 | D58: 45817 | E58: =2900000000*1.11 -> 3.219e+09 | F58: 10 | G58: 183403502 | H58: Paid | I58: 45768
A59: PT ATRYA TEKNIKA KONSULINDO | B59: PENGAWAS PEMBANGUNAN | C59: 45250 | D59: 45817 | E59: =2900000000*1.11 -> 3.219e+09 | F59: 11 | G59: 183403501 | H59: Paid | I59: 45799
A60: PT ATRYA TEKNIKA KONSULINDO | B60: PENGAWAS PEMBANGUNAN | C60: 45250 | D60: 45817 | E60: =2900000000*1.11 -> 3.219e+09 | F60: 12 | G60: 183403501 | H60: Paid | I60: 45827
... A65: PT ATRYA TEKNIKA KONSULINDO | B65: PENGAWAS PEMBANGUNAN | C65: 45250 | D65: 45817 | E65: =2900000000*1.11 -> 3.219e+09 | F65: 17 | G65: 207858350 | H65: Paid | I65: 45989
A66: PT GLOBE ENERGI INDONESIA | B66: JASA PENGURUSAN PERSETUJUAN BANGUNAN GEDUNG (PBG) DAN SERTIFIKAT LAIK FUNGSI (SLF) TAMBAK UDANG DI SUMBAWA | C66: 45314 | D66: 45770 | E66: 456654000 | F66: 1 | G66: 40559400 | H66: Paid | I66: 45316
A67: PT GLOBE ENERGI INDONESIA | B67: JASA PENGURUSAN PERSETUJUAN BANGUNAN GEDUNG (PBG) DAN SERTIFIKAT LAIK FUNGSI (SLF) TAMBAK UDANG DI SUMBAWA | C67: 45314 | D67: 45770 | E67: 456654000 | F67: 2 | G67: 101398500 | H67: Paid | I67: 45345
A68: PT GLOBE ENERGI INDONESIA | B68: JASA PENGURUSAN PERSETUJUAN BANGUNAN GEDUNG (PBG) DAN SERTIFIKAT LAIK FUNGSI (SLF) TAMBAK UDANG DI SUMBAWA | C68: 45314 | D68: 45770 | E68: 456654000 | F68: 3 | G68: 81118800 | H68: Paid | I68: 45558
A69: PT GLOBE ENERGI INDONESIA | B69: JASA PENGURUSAN PERSETUJUAN BANGUNAN GEDUNG (PBG) DAN SERTIFIKAT LAIK FUNGSI (SLF) TAMBAK UDANG DI SUMBAWA | C69: 45314 | D69: 45770 | E69: 456654000 | F69: 4 | G69: 116788650 | H69: Paid | I69: 45695
A70: PT GLOBE ENERGI INDONESIA | B70: JASA PENGURUSAN PERSETUJUAN BANGUNAN GEDUNG (PBG) DAN SERTIFIKAT LAIK FUNGSI (SLF) TAMBAK UDANG DI SUMBAWA | C70: 45314 | D70: 45770 | E70: 456654000 | F70: 5 | G70: 58394325 | H70: Paid | I70: 45964
A71: PT TOYASAE BERKAH ABADI | B71: JASA PENGADAAN POMPA | C71: 45455 | D71: 46430 | E71: 7376372103 | F71: 1 | G71: 2212911631 | H71: Paid | I71: 45478
A72: PT TOYASAE BERKAH ABADI | B72: JASA PENGADAAN POMPA | C72: 45455 | D72: 46430 | E72: 7376372103 | F72: 2 | G72: 3688186052 | H72: Paid | I72: 45622
A73: PT TOYASAE BERKAH ABADI | B73: JASA INSTALASI POMPA AIR DI SUMBAWA | C73: 45455 | D73: 46430 | E73: 929757897 | F73: 1 | G73: 251034632 | H73: Paid | I73: 45478
A74: PT TOYASAE BERKAH ABADI | B74: JASA INSTALASI POMPA AIR DI SUMBAWA | C74: 45455 | D74: 46430 | E74: 929757897 | F74: 2 | G74: 175724243 | H74: Paid | I74: 45849
A75: PT TOYASAE BERKAH ABADI | B75: JASA INSTALASI POMPA AIR DI SUMBAWA | C75: 45455 | D75: 46430 | E75: 929757897 | F75: 3 | G75: 246013940 | H75: Paid | I75: 45849
A76: PT TOYASAE BERKAH ABADI | B76: JASA INSTALASI LANJUTAN POMPA AIR DI SUMBAWA | C76: 45455 | D76: 46430 | E76: 1596180000 | F76: 1 | G76: 478854000 | H76: Paid | I76: 45897
A77: PT TOYASAE BERKAH ABADI | B77: JASA INSTALASI LANJUTAN POMPA AIR DI SUMBAWA | C77: 45455 | D77: 46430 | E77: 1596180000 | F77: 2 | G77: 319236000 | H77: Paid | I77: 46013
... A79: PT TOYASAE BERKAH ABADI | B79: PEKERJAAN PUMP HOUSE AREA POND | C79: 45455 | D79: 46430 | E79: 1104450000 | F79: 1 | G79: 662670000 | H79: Paid | I79: 46006
...

Sheet Lembar1
A1: RAJAWALI KONSULTAN | B1: =SUMIFS(Sheet1!G:G,Sheet1!A:A,Lembar1!A1) -> 36000000 | D1: INNAQU & RAJAWALI FIRM | E1: =SUMIFS('[1]DATA KONTRAK UPDATE'!$N:$N,'[1]DATA KONTRAK UPDATE'!$J:$J,D1)+SUMIFS('[1]DATA KONTRAK UPDATE'!$O:$O,'[1]DATA KONTRAK UPDATE'!$J:$J,D1) -> #VALUE! | F1: =B1-E1 -> #VALUE!
A2: PT Mipcon Konsultan Utama | B2: =SUMIFS(Sheet1!G:G,Sheet1!A:A,Lembar1!A2) -> 658096800 | D2: INNAQU&MIPCON | E2: =SUMIFS('[1]DATA KONTRAK UPDATE'!$N:$N,'[1]DATA KONTRAK UPDATE'!$J:$J,D2)+SUMIFS('[1]DATA KONTRAK UPDATE'!$O:$O,'[1]DATA KONTRAK UPDATE'!$J:$J,D2) -> #VALUE! | F2: =B2-E2 -> #VALUE!
A3: PT ATRYA SWASCIPTA REKAYASA | B3: =SUMIFS(Sheet1!G:G,Sheet1!A:A,Lembar1!A3) -> 3006046500 | D3: INNAQU&ASR | E3: =SUMIFS('[1]DATA KONTRAK UPDATE'!$N:$N,'[1]DATA KONTRAK UPDATE'!$J:$J,D3)+SUMIFS('[1]DATA KONTRAK UPDATE'!$O:$O,'[1]DATA KONTRAK UPDATE'!$J:$J,D3) -> #VALUE! | F3: =B3-E3 -> #VALUE!
A4: PT ENVITEK INDONESIA JAYA | B4: =SUMIFS(Sheet1!G:G,Sheet1!A:A,Lembar1!A4) -> 4376412376 | D4: INNAQU&ENVITEK | E4: =SUMIFS('[1]DATA KONTRAK UPDATE'!$N:$N,'[1]DATA KONTRAK UPDATE'!$J:$J,D4)+SUMIFS('[1]DATA KONTRAK UPDATE'!$O:$O,'[1]DATA KONTRAK UPDATE'!$J:$J,D4) -> #VALUE! | F4: =B4-E4 -> #VALUE!
A5: PT ADONARA BAKTI BANGSA | B5: =SUMIFS(Sheet1!G:G,Sheet1!A:A,Lembar1!A5) -> 4607158912 | D5: INNAQU&ABB | E5: =SUMIFS('[1]DATA KONTRAK UPDATE'!$N:$N,'[1]DATA KONTRAK UPDATE'!$J:$J,D5)+SUMIFS('[1]DATA KONTRAK UPDATE'!$O:$O,'[1]DATA KONTRAK UPDATE'!$J:$J,D5) -> #VALUE! | F5: =B5-E5 -> #VALUE!
A6: PT ATRYA TEKNIKA KONSULINDO | B6: =SUMIFS(Sheet1!G:G,Sheet1!A:A,Lembar1!A6) -> 3260546319 | D6: INNAQU&ATK | E6: =SUMIFS('[1]DATA KONTRAK UPDATE'!$N:$N,'[1]DATA KONTRAK UPDATE'!$J:$J,D6)+SUMIFS('[1]DATA KONTRAK UPDATE'!$O:$O,'[1]DATA KONTRAK UPDATE'!$J:$J,D6) -> #VALUE! | F6: =B6-E6 -> #VALUE!
A7: PT GLOBE ENERGI INDONESIA | B7: =SUMIFS(Sheet1!G:G,Sheet1!A:A,Lembar1!A7) -> 939093855 | D7: INNAQU&GEI | E7: =SUMIFS('[1]DATA KONTRAK UPDATE'!$N:$N,'[1]DATA KONTRAK UPDATE'!$J:$J,D7)+SUMIFS('[1]DATA KONTRAK UPDATE'!$O:$O,'[1]DATA KONTRAK UPDATE'!$J:$J,D7) -> #VALUE! | F7: =B7-E7 -> #VALUE!
A8: PT TOYASAE BERKAH ABADI | B8: =SUMIFS(Sheet1!G:G,Sheet1!A:A,Lembar1!A8) -> 8353866498 | D8: INNAQU&TBA | E8: =SUMIFS('[1]DATA KONTRAK UPDATE'!$N:$N,'[1]DATA KONTRAK UPDATE'!$J:$J,D8)+SUMIFS('[1]DATA KONTRAK UPDATE'!$O:$O,'[1]DATA KONTRAK UPDATE'!$J:$J,D8) -> #VALUE! | F8: =B8-E8 -> #VALUE!
A9: PT A VAN KAICK INDONESIA | B9: =SUMIFS(Sheet1!G:G,Sheet1!A:A,Lembar1!A9) -> 7694187000 | D9: INNAQU&AVK | E9: =SUMIFS('[1]DATA KONTRAK UPDATE'!$N:$N,'[1]DATA KONTRAK UPDATE'!$J:$J,D9)+SUMIFS('[1]DATA KONTRAK UPDATE'!$O:$O,'[1]DATA KONTRAK UPDATE'!$J:$J,D9) -> #VALUE! | F9: =B9-E9 -> #VALUE!
A10: KSO PRIMA DWI SEJAHTERA | B10: =SUMIFS(Sheet1!G:G,Sheet1!A:A,Lembar1!A10) -> 57172644232 | D10: INNAQU&PDM | E10: =SUMIFS('[1]DATA KONTRAK UPDATE'!$N:$N,'[1]DATA KONTRAK UPDATE'!$J:$J,D10)+SUMIFS('[1]DATA KONTRAK UPDATE'!$O:$O,'[1]DATA KONTRAK UPDATE'!$J:$J,D10) -> #VALUE! | F10: =B10-E11 -> #VALUE!
A11: PT PRIMA DWI MITRA | B11: =SUMIFS(Sheet1!G:G,Sheet1!A:A,Lembar1!A11) -> 2296247653 | D11: INNAQU&KSO PDS | E11: =SUMIFS('[1]DATA KONTRAK UPDATE'!$N:$N,'[1]DATA KONTRAK UPDATE'!$J:$J,D11)+SUMIFS('[1]DATA KONTRAK UPDATE'!$O:$O,'[1]DATA KONTRAK UPDATE'!$J:$J,D11) -> #VALUE! | F11: =B11-E10 -> #VALUE!
A12: PT LAUTAN DELTAMAS SEJAHTERA | B12: 8789692671 | D12: INNAQU&LDS | E12: =SUMIFS('[1]DATA KONTRAK UPDATE'!$N:$N,'[1]DATA KONTRAK UPDATE'!$J:$J,D12)+SUMIFS('[1]DATA KONTRAK UPDATE'!$O:$O,'[1]DATA KONTRAK UPDATE'!$J:$J,D12) -> #VALUE! | F12: =B12-E12 -> #VALUE!
A13: PT EISE BUMI SEJAHTERA | B13: =SUMIFS(Sheet1!G:G,Sheet1!A:A,Lembar1!A13) -> 5.5695292e+09 | D13: INNAQU&EBS | E13: =SUMIFS('[1]DATA KONTRAK UPDATE'!$N:$N,'[1]DATA KONTRAK UPDATE'!$J:$J,D13)+SUMIFS('[1]DATA KONTRAK UPDATE'!$O:$O,'[1]DATA KONTRAK UPDATE'!$J:$J,D13) -> #VALUE! | F13: =B13-E13 -> #VALUE!
A14: LMATS CONSULTING | B14: =SUMIFS(Sheet1!G:G,Sheet1!A:A,Lembar1!A14) -> 57165000 | D14: INNAQU&LMATS | E14: =SUMIFS('[1]DATA KONTRAK UPDATE'!$N:$N,'[1]DATA KONTRAK UPDATE'!$J:$J,D14)+SUMIFS('[1]DATA KONTRAK UPDATE'!$O:$O,'[1]DATA KONTRAK UPDATE'!$J:$J,D14) -> #VALUE! | F14: =B14-E14 -> #VALUE!
A15: PT INCA MANDIRI INTERNUSA | B15: =SUMIFS(Sheet1!G:G,Sheet1!A:A,Lembar1!A15) -> 386737800 | D15: INNAQU&IMI | E15: =SUMIFS('[1]DATA KONTRAK UPDATE'!$N:$N,'[1]DATA KONTRAK UPDATE'!$J:$J,D15)+SUMIFS('[1]DATA KONTRAK UPDATE'!$O:$O,'[1]DATA KONTRAK UPDATE'!$J:$J,D15) -> #VALUE! | F15: =B15-E15 -> #VALUE!
A16: ADY TULUS SUCIPTO | B16: =SUMIFS(Sheet1!G:G,Sheet1!A:A,Lembar1!A16) -> 408000000 | D16: INNAQU&Ady Tulus | E16: =SUMIFS('[1]DATA KONTRAK UPDATE'!$N:$N,'[1]DATA KONTRAK UPDATE'!$J:$J,D16)+SUMIFS('[1]DATA KONTRAK UPDATE'!$O:$O,'[1]DATA KONTRAK UPDATE'!$J:$J,D16) -> #VALUE! | F16: =B16-E16 -> #VALUE!
A17: ESTER HENDRA | B17: =SUMIFS(Sheet1!G:G,Sheet1!A:A,Lembar1!A17) -> 18333333 | D17: INNAQU&ESTER HENDRA | E17: =SUMIFS('[1]DATA KONTRAK UPDATE'!$N:$N,'[1]DATA KONTRAK UPDATE'!$J:$J,D17)+SUMIFS('[1]DATA KONTRAK UPDATE'!$O:$O,'[1]DATA KONTRAK UPDATE'!$J:$J,D17) -> #VALUE! | F17: =B17-E17 -> #VALUE!
A18: KAP BUDIARTHA & ANGGIRIAWAN | B18: =SUMIFS(Sheet1!G:G,Sheet1!A:A,Lembar1!A18) -> 65000000 | D18: INNAQU&KAP BUDIARTHA | E18: =SUMIFS('[1]DATA KONTRAK UPDATE'!$N:$N,'[1]DATA KONTRAK UPDATE'!$J:$J,D18)+SUMIFS('[1]DATA KONTRAK UPDATE'!$O:$O,'[1]DATA KONTRAK UPDATE'!$J:$J,D18) -> #VALUE! | F18: =B18-E18 -> #VALUE!
A19: KKA ARYA BAGIASTRA | B19: =SUMIFS(Sheet1!G:G,Sheet1!A:A,Lembar1!A19) -> 11100000 | D19: INNAQU&ADT | E19: =SUMIFS('[1]DATA KONTRAK UPDATE'!$N:$N,'[1]DATA KONTRAK UPDATE'!$J:$J,D19)+SUMIFS('[1]DATA KONTRAK UPDATE'!$O:$O,'[1]DATA KONTRAK UPDATE'!$J:$J,D19) -> #VALUE! | F19: =B19-E27 -> #VALUE!
A20: PT AFNAN DEVA TEKHNIK | B20: =SUMIFS(Sheet1!G:G,Sheet1!A:A,Lembar1!A20) -> 3017951611 | D20: INNAQU&CV ALFI | E20: =SUMIFS('[1]DATA KONTRAK UPDATE'!$N:$N,'[1]DATA KONTRAK UPDATE'!$J:$J,D20)+SUMIFS('[1]DATA KONTRAK UPDATE'!$O:$O,'[1]DATA KONTRAK UPDATE'!$J:$J,D20) -> #VALUE! | F20: =B20-E19 -> #VALUE!
A21: CV ALFI SAMAWA RENT CAR | B21: =SUMIFS(Sheet1!G:G,Sheet1!A:A,Lembar1!A21) -> 225800000 | D21: INNAQU&DENI GUSTARIANA | E21: =SUMIFS('[1]DATA KONTRAK UPDATE'!$N:$N,'[1]DATA KONTRAK UPDATE'!$J:$J,D21)+SUMIFS('[1]DATA KONTRAK UPDATE'!$O:$O,'[1]DATA KONTRAK UPDATE'!$J:$J,D21) -> #VALUE! | F21: =B21-E20 -> #VALUE!
A22: I KETUT DENI GUSTARIANA | B22: =SUMIFS(Sheet1!G:G,Sheet1!A:A,Lembar1!A22) -> 344444444 | D22: INNAQU&REALIS | E22: =SUMIFS('[1]DATA KONTRAK UPDATE'!$N:$N,'[1]DATA KONTRAK UPDATE'!$J:$J,D22)+SUMIFS('[1]DATA KONTRAK UPDATE'!$O:$O,'[1]DATA KONTRAK UPDATE'!$J:$J,D22) -> #VALUE! | F22: =B22-E21 -> #VALUE!
A23: PT Realis Surya Brahmesta | B23: =SUMIFS(Sheet1!G:G,Sheet1!A:A,Lembar1!A23) -> 145543755 | D23: INNAQU&SCB | E23: =SUMIFS('[1]DATA KONTRAK UPDATE'!$N:$N,'[1]DATA KONTRAK UPDATE'!$J:$J,D23)+SUMIFS('[1]DATA KONTRAK UPDATE'!$O:$O,'[1]DATA KONTRAK UPDATE'!$J:$J,D23) -> #VALUE! | F23: =B23-E22 -> #VALUE!
A24: PT SAPODIA CAHAYA BERSAMA | B24: =SUMIFS(Sheet1!G:G,Sheet1!A:A,Lembar1!A24) -> 2786914868 | D24: INNAQU&MAA | E24: =SUMIFS('[1]DATA KONTRAK UPDATE'!$N:$N,'[1]DATA KONTRAK UPDATE'!$J:$J,D24)+SUMIFS('[1]DATA KONTRAK UPDATE'!$O:$O,'[1]DATA KONTRAK UPDATE'!$J:$J,D24) -> #VALUE! | F24: =B24-E23 -> #VALUE!
A25: PT MEGA ARTHA ANANTA | B25: =SUMIFS(Sheet1!G:G,Sheet1!A:A,Lembar1!A25) -> 4772373491 | D25: INNAQU&PARAHITA | E25: =SUMIFS('[1]DATA KONTRAK UPDATE'!$N:$N,'[1]DATA KONTRAK UPDATE'!$J:$J,D25)+SUMIFS('[1]DATA KONTRAK UPDATE'!$O:$O,'[1]DATA KONTRAK UPDATE'!$J:$J,D25) -> #VALUE! | F25: =B25-E24 -> #VALUE!
A26: PT PARAHITA INTI RAYA | B26: =SUMIFS(Sheet1!G:G,Sheet1!A:A,Lembar1!A26) -> 14239617744 | D26: INNAQU&TRADECORP | E26: =SUMIFS('[1]DATA KONTRAK UPDATE'!$N:$N,'[1]DATA KONTRAK UPDATE'!$J:$J,D26)+SUMIFS('[1]DATA KONTRAK UPDATE'!$O:$O,'[1]DATA KONTRAK UPDATE'!$J:$J,D26) -> #VALUE! | F26: =B26-E25 -> #VALUE!
A27: TRADECORP | B27: =SUMIFS(Sheet1!G:G,Sheet1!A:A,Lembar1!A27) -> 1455250420 | D27: INNAQU&KKA ARYA | E27: =SUMIFS('[1]DATA KONTRAK UPDATE'!$N:$N,'[1]DATA KONTRAK UPDATE'!$J:$J,D27)+SUMIFS('[1]DATA KONTRAK UPDATE'!$O:$O,'[1]DATA KONTRAK UPDATE'!$J:$J,D27) -> #VALUE! | F27: =B27-E26 -> #VALUE!
A28: KSO SPLIT LDS-MAA | B28: =SUMIFS(Sheet1!G:G,Sheet1!A:A,Lembar1!A28) -> 30962621012 | D28: INNAQU &KSO LMA | E28: =SUMIFS('[1]DATA KONTRAK UPDATE'!$N:$N,'[1]DATA KONTRAK UPDATE'!$J:$J,D28)+SUMIFS('[1]DATA KONTRAK UPDATE'!$O:$O,'[1]DATA KONTRAK UPDATE'!$J:$J,D28) -> #VALUE! | F28: =B28-E28 -> #VALUE!
A29: PT ARTHA BUANA ANANTA | B29: =SUMIFS(Sheet1!G:G,Sheet1!A:A,Lembar1!A29) -> 3190079775 | D29: INNAQU&ABA | E29: =SUMIFS('[1]DATA KONTRAK UPDATE'!$N:$N,'[1]DATA KONTRAK UPDATE'!$J:$J,D29)+SUMIFS('[1]DATA KONTRAK UPDATE'!$O:$O,'[1]DATA KONTRAK UPDATE'!$J:$J,D29) -> #VALUE! | F29: =B29-E29 -> #VALUE!
